Workbook
Name NativeTimeline_Fecha1: #N/A
Name NativeTimeline_Fecha2: #N/A
Name SegmentaciónDeDatos_C.C.: #N/A
Name SegmentaciónDeDatos_C.C.1: #N/A
Name SegmentaciónDeDatos_Cuenta1: #N/A
Name SegmentaciónDeDatos_Cuenta11: #N/A
Name SegmentaciónDeDatos_Detalle: #N/A
Name SegmentaciónDeDatos_Detalle1: #N/A
Name SegmentaciónDeDatos_Mes: #N/A
Name SegmentaciónDeDatos_Nombre_Solicitante: #N/A
Name SegmentaciónDeDatos_Nombre_Solicitante1: #N/A
Name SegmentaciónDeDatos_Nro_Rend.: #N/A

Sheet Proyeccion 2025
C1: Heca - Chile
C2: Proyeccion de Efectivo y de necesidades de financiamiento
C3: del 01/01/2025 al 31/12/2025
C5: 45658 | D5: 45689 | E5: 45717 | F5: 45748 | G5: 45778 | H5: 45809 | I5: 45839 | J5: 45870 | K5: 45901 | L5: 45931 | M5: 45962 | N5: 45992
B6: Ventas | C6: 500000000 | D6: 650000000 | E6: 700000000 | F6: =+E6*1.03 -> 721000000 | G6: =+F6*1.03 -> 742630000 | H6: =+G6*1.03 -> 764908900 | I6: =+H6*1.03 -> 787856167 | J6: =+I6*1.03 -> 8.1149185e+08 | K6: =+J6*1.03 -> 8.3583661e+08 | L6: =+K6*1.03 -> 8.6091171e+08 | M6: =+L6*1.03 -> 8.8673906e+08 | N6: =+M6*1.03 -> 9.1334123e+08
B7: Ingresos
B8: Total Ingresos | C8: =+C6 -> 500000000 | D8: =+D6 -> 650000000 | E8: =+E6 -> 700000000 | F8: =+F6 -> 721000000 | G8: =+G6 -> 742630000 | H8: =+H6 -> 764908900 | I8: =+I6 -> 787856167 | J8: =+J6 -> 8.1149185e+08 | ... N8: =+N6 -> 9.1334123e+08
B9: Egresos
B10: Compras | C10: =+C8*50% -> 250000000 | D10: =+D8*50% -> 325000000 | E10: =+E8*50% -> 350000000 | F10: =+F8*50% -> 360500000 | G10: =+G8*50% -> 371315000 | H10: =+H8*50% -> 382454450 | I10: =+I8*50% -> 3.9392808e+08 | J10: =+J8*50% -> 4.0574593e+08 | ... N10: =+N8*50% -> 4.5667061e+08
B11: Gasto General | C11: =C30 -> 1.2759667e+08 | D11: =D30 -> 91321694 | E11: =E30 -> 99450000 | F11: =F30 -> 86450000 | G11: =G30 -> 86450000 | H11: =H30 -> 82950000 | I11: =I30 -> 82950000 | J11: =J30 -> 82950000 | ... N11: =N30 -> 82950000
B12: Cancelacion de Pasivos | D12: =27152000+27254400 -> 54406400 | E12: 29924650
B13: Total Egresos | C13: =+SUM(C10:C12) -> 3.7759667e+08 | D13: =+SUM(D10:D12) -> 4.7072809e+08 | E13: =+SUM(E10:E12) -> 479374650 | F13: =+SUM(F10:F12) -> 446950000 | G13: =+SUM(G10:G12) -> 457765000 | H13: =+SUM(H10:H12) -> 465404450 | I13: =+SUM(I10:I12) -> 4.7687808e+08 | J13: =+SUM(J10:J12) -> 4.8869593e+08 | ... N13: =+SUM(N10:N12) -> 5.3962061e+08
B15: Total al final de mes | C15: =+C8-C13 -> 1.2240333e+08 | D15: =+D8-D13 -> 1.7927191e+08 | E15: =+E8-E13 -> 220625350 | F15: =+F8-F13 -> 274050000 | G15: =+G8-G13 -> 284865000 | H15: =+H8-H13 -> 299504450 | I15: =+I8-I13 -> 3.1097808e+08 | J15: =+J8-J13 -> 3.2279593e+08 | ... N15: =+N8-N13 -> 3.7372061e+08
B21: Gastos de Oficina | C21: 6502027 | D21: 4545177 | E21: 6000000 | F21: 6000000 | G21: 6000000 | H21: 2500000 | I21: 2500000 | J21: 2500000 | K21: 2500000 | L21: 2500000 | M21: 2500000 | N21: 2500000 | O21: =SUM(C21:N21) -> 46547204
B22: Gastos de Operaciones | C22: 26362481 | D22: 14384193 | E22: 12000000 | F22: 7000000 | G22: 7000000 | H22: 7000000 | I22: 7000000 | J22: 7000000 | K22: 7000000 | L22: 7000000 | M22: 7000000 | N22: 7000000 | O22: =SUM(C22:N22) -> 1.1574667e+08
B23: Gastos de Importacion | O23: =SUM(C23:N23) -> 0
B24: Siga Sonriendo | C24: 1450000 | D24: =+C24 -> 1450000 | E24: =+D24 -> 1450000 | F24: =+E24 -> 1450000 | G24: =+F24 -> 1450000 | H24: =+G24 -> 1450000 | I24: =+H24 -> 1450000 | J24: =+I24 -> 1450000 | K24: =+J24 -> 1450000 | ... N24: =+M24 -> 1450000 | O24: =SUM(C24:N24) -> 17400000
B25: Gastos Financieros | C25: 1249537 | D25: 1061503 | E25: 1000000 | F25: 1000000 | G25: 1000000 | H25: 1000000 | I25: 1000000 | J25: 1000000 | K25: 1000000 | L25: 1000000 | M25: 1000000 | N25: 1000000 | O25: =SUM(C25:N25) -> 12311040
B26: Gastos de Personal | C26: 46032254 | D26: 31313984 | E26: 40000000 | F26: 32000000 | G26: 32000000 | H26: 32000000 | I26: 32000000 | J26: 32000000 | K26: 32000000 | L26: 32000000 | M26: 32000000 | N26: 32000000 | O26: =SUM(C26:N26) -> 4.0534624e+08
B27: Gastos Extras | C27: 38000000 | D27: =+C27 -> 38000000 | E27: =+D27 -> 38000000 | F27: =+E27 -> 38000000 | G27: =+F27 -> 38000000 | H27: =+G27 -> 38000000 | I27: =+H27 -> 38000000 | J27: =+I27 -> 38000000 | K27: =+J27 -> 38000000 | ... N27: =+M27 -> 38000000 | O27: =SUM(C27:N27) -> 456000000
B28: Gasto Tax Ingenieria | C28: 8000374 | D28: 566837 | E28: 1000000 | F28: 1000000 | G28: 1000000 | H28: 1000000 | I28: 1000000 | J28: 1000000 | K28: 1000000 | L28: 1000000 | M28: 1000000 | N28: 1000000 | O28: =SUM(C28:N28) -> 18567211
C30: =SUM(C21:C29) -> 1.2759667e+08 | D30: =SUM(D21:D28) -> 91321694 | E30: =SUM(E21:E28) -> 99450000 | F30: =SUM(F21:F28) -> 86450000 | G30: =SUM(G21:G28) -> 86450000 | H30: =SUM(H21:H28) -> 82950000 | I30: =SUM(I21:I28) -> 82950000 | J30: =SUM(J21:J28) -> 82950000 | K30: =SUM(K21:K28) -> 82950000 | ... N30: =SUM(N21:N28) -> 82950000
B33: Gastos Generales Insumos Medicos | C33: =SUM(C34:C38) -> 12800000 | D33: =SUM(D34:D38) -> 23800500 | E33: =SUM(E34:E38) -> 12801000 | F33: =SUM(F34:F38) -> 12801501 | G33: =SUM(G34:G38) -> 23802002 | H33: =SUM(H34:H38) -> 12802503 | I33: =SUM(I34:I38) -> 12803004 | J33: =SUM(J34:J38) -> 23803505 | ... N33: =SUM(N34:N38) -> 12805514 | O33: =SUM(C33:N33) -> 1.9763306e+08
B34: Gastos de Oficina | C34: 800000 | D34: 800000 | E34: 800000 | F34: 800000 | G34: 800000 | H34: 800000 | I34: 800000 | J34: 800000 | K34: 800000 | L34: 800000 | M34: 800000 | N34: 800000
B35: Gastos Operacionales | C35: 1500000 | D35: 1500000 | E35: 1500000 | F35: 1500000 | G35: 1500000 | H35: 1500000 | I35: 1500000 | J35: 1500000 | K35: 1500000 | L35: 1500000 | M35: 1500000 | N35: 1500000
B36: Gastos de Viajes | C36: 1000000 | D36: =+C36*1.0005 -> 1000500 | E36: =+D36*1.0005 -> 1001000.2 | F36: =+E36*1.0005 -> 1001500.8 | G36: =+F36*1.0005 -> 1002001.5 | H36: =+G36*1.0005 -> 1002502.5 | I36: =+H36*1.0005 -> 1003003.8 | J36: =+I36*1.0005 -> 1003505.3 | K36: =+J36*1.0005 -> 1004007 | ... N36: =+M36*1.0005 -> 1005513.8
B37: Gastos extras | D37: 11000000 | G37: 11000000 | J37: 11000000 | L37: 11000000
B38: Gastos de Personal | C38: 9500000 | D38: 9500000 | E38: 9500000 | F38: 9500000 | G38: 9500000 | H38: 9500000 | I38: 9500000 | J38: 9500000 | K38: 9500000 | L38: 9500000 | M38: 9500000 | N38: 9500000

Sheet Reporte 
C6: Reporte Mensual Rendiciones
C7: CL
C8: julio | E8: junio
B9: Rendiciones | C9: Neto | D9: Exento | E9: Neto | F9: Exento
B10: Air Heca | C10: 156941 | D10: 2852629 | E10: 250924 | F10: 5380655.7
B11: Operacionales | C11: 156941 | D11: 2852629 | E11: 250924 | F11: 5380655.7
B12: Total general | C12: 156941 | D12: 2852629 | E12: 250924 | F12: 5380655.7

Sheet Dashboard
B1: Fecha | C1: (Todas)
B3: Suma de Total
C4: julio | D4: junio | E4: Total general
B6: Operacionales | C6: 560250.17 | D6: 5324975.7 | E6: 5885225.9
B7: Bencina | D7: 118401 | E7: 118401
B8: Comidas y Bebidas | C8: 40369.6 | D8: 941620 | E8: 981989.6
B9: Envíos y encomiendas | C9: 24876.57 | D9: 91666 | E9: 116542.57
B10: Gastos de Viajes | C10: 495004 | E10: 495004
B11: Gastos Varios | D11: 44471.46 | E11: 44471.46
B12: Hospedaje | D12: 2340839 | E12: 2340839
B13: Peajes / Estacionamientos | D13: 125373 | E13: 125373
B14: Taxi - Uber | D14: 44261 | E14: 44261
B15: Gastos de Vehiculo | D15: 1618344.2 | E15: 1618344.2
B16: Total general | C16: 560250.17 | D16: 5324975.7 | E16: 5885225.9

Sheet Bancos 
B3: Reporte bancos HGI
B4: Bancos | C4: Rendiciones
C5: 2026 | M5: Total 2026 | N5: Total general
C6: ene | D6: feb | E6: mar | F6: abr | G6: may | H6: jun | I6: jul | J6: ago | K6: sept | L6: oct
B7: Chile
B8: Banco Internacional HGI | C8: 5599945.8 | D8: 2493217.6 | E8: 2449369.4 | F8: 2794773.7 | G8: 4614671.1 | H8: 1025796.6 | I8: 4329942.4 | J8: 1243366.3 | K8: 347577 | L8: 136520 | M8: 25035180 | N8: 25035180
B9: Adolfo Quintana | E9: 9157 | M9: 9157 | N9: 9157
B10: Alejandra Olivares | C10: 98560 | D10: 73464 | M10: 172024 | N10: 172024
B11: Brigitte Moran Mesa | C11: 400000 | G11: 443203.83 | I11: 900000 | M11: 1743203.8 | N11: 1743203.8
B12: Dailin Arellano | C12: 85348 | D12: 1246866 | F12: 535856.26 | G12: 1176889.4 | M12: 3044959.6 | N12: 3044959.6
B13: David Herce | C13: 2776652.4 | D13: 204639.42 | E13: 1509451.3 | F13: 420684.72 | G13: 49308 | H13: 354529 | I13: 140778 | J13: 70388.92 | M13: 5526431.8 | N13: 5526431.8
B14: Davis Torres | D14: 52286 | E14: 133629.1 | G14: 40019.95 | J14: 127195.53 | M14: 353130.58 | N14: 353130.58
B15: Javier Salazar | C15: 602683.18 | D15: 287717.01 | M15: 890400.19 | N15: 890400.19
B16: Manuel Guajardo | D16: 57343.17 | M16: 57343.17 | N16: 57343.17
B17: Mariangel Veloz | D17: 169414 | E17: 30393 | F17: 673690.91 | G17: 38990 | H17: 437147.92 | I17: 171201.14 | J17: 16759.96 | M17: 1537596.9 | N17: 1537596.9
B18: Raul Diaz | C18: 300000 | D18: 375320 | E18: 161732.72 | F18: 598791.36 | G18: 471274.93 | H18: 195970.71 | I18: 309838.64 | J18: 321274 | K18: 347577 | L18: 136520 | M18: 3218299.4 | N18: 3218299.4
B19: Tomas Castro | C19: 1298352 | D19: 26168 | E19: 50000 | F19: 26471 | G19: 604080 | H19: 20000 | I19: 1686739 | J19: 24516 | M19: 3736326 | N19: 3736326
B20: Deisy Sierra | F20: 103357.45 | I20: 211298.78 | J20: 529691.91 | M20: 844348.14 | N20: 844348.14
B21: Edgar hernandez | C21: 38350.19 | M21: 38350.19 | N21: 38350.19
B22: Abel Kottwitz | E22: 555006.3 | F22: 435922 | G22: 1790905 | H22: 18149 | I22: 785086.83 | J22: 149340 | M22: 3734409.1 | N22: 3734409.1
B23: Pia Cotronea | I23: 125000 | M23: 125000 | N23: 125000
B24: (en blanco) | I24: 125000 | M24: 125000 | N24: 125000
B25: Yohana Morillo | J25: 4200 | M25: 4200 | N25: 4200
B26: Scotianbank CLP | C26: 1933058.1 | E26: 790277 | H26: 3208366.4 | I26: 9573297.2 | J26: 2572787.6 | M26: 18077786 | N26: 18077786
B27: Alejandra Olivares | C27: 38711 | M27: 38711 | N27: 38711
B28: Brigitte Moran Mesa | C28: 402023 | H28: 850000 | I28: 454931.94 | M28: 1706954.9 | N28: 1706954.9
B29: Dailin Arellano | E29: 790277 | H29: 222315 | I29: 512688.77 | M29: 1525280.8 | N29: 1525280.8
B30: David Herce | H30: 148778.38 | J30: 775838.4 | M30: 924616.78 | N30: 924616.78
B31: Mariangel Veloz | J31: 545740 | M31: 545740 | N31: 545740
B32: Raul Diaz | H32: 91070.42 | I32: 241312 | J32: 331825.08 | M32: 664207.5 | N32: 664207.5
B33: Tomas Castro | C33: 1243599 | H33: 57871 | M33: 1301470 | N33: 1301470
B34: Edgar hernandez | C34: 248725.07 | M34: 248725.07 | N34: 248725.07
B35: Abel Kottwitz | H35: 1484052 | J35: 419384.14 | M35: 1903436.1 | N35: 1903436.1
B36: Rodrigo Ibañez | H36: 354279.56 | I36: 8364364.5 | M36: 8718644.1 | N36: 8718644.1
B37: 1 | H37: 354279.56 | M37: 354279.56 | N37: 354279.56
B38: 2 | I38: 2479139 | M38: 2479139 | N38: 2479139
B39: 3 | I39: 5885225.5 | M39: 5885225.5 | N39: 5885225.5
B40: Edynar Monsalbe | J40: 500000 | M40: 500000 | N40: 500000
B41: 1 | J41: 500000 | M41: 500000 | N41: 500000
B42: Total general | C42: 7533003.8 | D42: 2493217.6 | E42: 3239646.4 | F42: 2794773.7 | G42: 4614671.1 | H42: 4234163 | I42: 13903240 | J42: 3816153.9 | K42: 347577 | L42: 136520 | M42: 43112966 | N42: 43112966

Sheet HGI
C6: Reporte Mensual Rendiciones
B7: Insumos medicos | C7: CL
B8: Rendiciones | C8: octubre | D8: enero | E8: febrero | F8: marzo | G8: abril | H8: mayo | I8: junio | J8: julio | K8: agosto | L8: Total general
B9: Adolfo Quintana | F9: 9157 | L9: 9157
B10: Alejandra Olivares | D10: 137271 | E10: 73464 | L10: 210735
B11: Brigitte Moran Mesa | D11: 769022.02 | H11: 476204.81 | I11: 951730.92 | J11: 1044741.7 | K11: 279646.91 | L11: 3521346.3
B12: Dailin Arellano | E12: 1118303 | F12: 1004188 | G12: 535856.26 | H12: 1174049.4 | I12: 320700 | J12: 380152.77 | L12: 4533249.4
B13: David Herce | D13: 2776652.4 | E13: 204639.42 | F13: 1509451.3 | G13: 420684.72 | H13: 49308 | I13: 503307.38 | J13: 140778 | K13: 846227.32 | L13: 6451048.5
B14: Davis Torres | E14: 52286 | F14: 133629.1 | H14: 370311.59 | I14: 30928.1 | J14: 21949.55 | K14: 144026.24 | L14: 753130.58
B15: Javier Salazar | D15: 602683.18 | E15: 287717.01 | L15: 890400.19
B16: Manuel Guajardo | E16: 57343.17 | L16: 57343.17
B17: Mariangel Veloz | E17: 169414 | F17: 30393 | G17: 670690.91 | H17: 38990 | I17: 465222.92 | J17: 171201.14 | K17: 562499.96 | L17: 2108411.9
B18: Raul Diaz | C18: 119300.42 | D18: 279475.74 | E18: 295844.02 | F18: 261732.96 | G18: 598791.36 | H18: 379054.93 | I18: 353823.07 | J18: 484368.21 | K18: 653099.01 | L18: 3425489.7
B19: Tomas Castro | D19: 2541951 | E19: 26168 | F19: 50000 | G19: 26471 | H19: 604080 | I19: 77871 | J19: 1686739 | K19: 213496 | L19: 5226776
B20: Deisy Sierra | G20: 103357.45 | J20: 211298.78 | K20: 529691.91 | L20: 844348.14
B21: Edgar hernandez | D21: 287075.26 | L21: 287075.26
B22: Abel Kottwitz | E22: 130755.15 | F22: 441251.15 | G22: 470590.62 | H22: 1852319.6 | I22: 2024147.3 | J22: 1009225.3 | K22: 721769.93 | L22: 6650059.1
B23: Rodrigo Ibañez | I23: 5679255.3 | J23: 3039388.8 | L23: 8718644.1
B24: Pia Cotronea | I24: 96032 | J24: 34040 | L24: 130072
B25: Yohana Morillo | K25: 4200 | L25: 4200
B26: Edynar Monsalbe | K26: 762889.96 | L26: 762889.96
B27: Total general | C27: 119300.42 | D27: 7394130.6 | E27: 2415933.8 | F27: 3439802.5 | G27: 2826442.3 | H27: 4944318.3 | I27: 10503018 | J27: 8223883.2 | K27: 4717547.2 | L27: 44584376
N32: 1635285
N33: 1299644.6 | P33: =+N32*P34 -> 1105869.4
N34: =+N33/N32 -> 0.79475113 | P34: 0.6762548
N36: 314049 | P36: =+N36 -> 314049
N37: =+N36/N32 -> 0.19204542
N39: 21591.41 | P39: =+N32-P33-P36 -> 215366.68
N40: =+N39/N32 -> 0.013203454 | P40: =+P39/N32 -> 0.13169978

Sheet Rendiciones
B3: =Rendiciones[[#Totals],[Saldo Fondo ]] -> 14185.203 | AA3: =30000/1.19 -> 25210.084
B4: Nombre Solicitante | C4: Nro Rend. | D4: Fecha | E4: Semana | F4: Mes | G4: C.C. | H4: Cuenta | I4: Detalle | J4: Concepto | K4: Tipo Doc | L4: Monto Neto | M4: Monto Exento | N4: Iva | O4: Total | P4: Pagado por | Q4: Fecha de Pago | R4: Monto | S4: Saldo Fondo | T4: Columna1
B5: Brigitte Moran Mesa | D5: 46031 | E5: Del 05 al 09 | F5: =IF(Rendiciones[[#This Row],[Fecha ]]<>"",TEXT(Rendiciones[[#This Row],[Fecha ]],"MMMM"),"") -> enero | G5: HGI. | N5: =Rendiciones[[#This Row],[Monto Neto ]]*19% -> 0 | O5: =+Rendiciones[[#This Row],[Monto Neto ]]+Rendiciones[[#This Row],[Monto Exento ]]+Rendiciones[[#This Row],[Iva]] -> 0 | P5: Banco Internacional HGI | Q5: 46031 | R5: 400000 | S5: =Rendiciones[[#This Row],[Total ]]-Rendiciones[[#This Row],[Monto ]] -> -400000
B6: Raul Diaz | D6: 46035 | E6: Del 12 al 16 | F6: =IF(Rendiciones[[#This Row],[Fecha ]]<>"",TEXT(Rendiciones[[#This Row],[Fecha ]],"MMMM"),"") -> enero | N6: =Rendiciones[[#This Row],[Monto Neto ]]*19% -> 0 | O6: =+Rendiciones[[#This Row],[Monto Neto ]]+Rendiciones[[#This Row],[Monto Exento ]]+Rendiciones[[#This Row],[Iva]] -> 0 | P6: Banco Internacional HGI | Q6: 46035 | R6: 300000 | S6: =Rendiciones[[#This Row],[Total ]]-Rendiciones[[#This Row],[Monto ]] -> -300000
B7: Alejandra Olivares | C7: 1 | D7: 46030 | E7: Del 05 al 09 | F7: =IF(Rendiciones[[#This Row],[Fecha ]]<>"",TEXT(Rendiciones[[#This Row],[Fecha ]],"MMMM"),"") -> enero | G7: HG | H7: Oficina | I7: Miscelaneos Administracion | M7: 35899 | N7: =Rendiciones[[#This Row],[Monto Neto ]]*19% -> 0 | O7: =+Rendiciones[[#This Row],[Monto Neto ]]+Rendiciones[[#This Row],[Monto Exento ]]+Rendiciones[[#This Row],[Iva]] -> 35899 | S7: =Rendiciones[[#This Row],[Total ]]-Rendiciones[[#This Row],[Monto ]] -> 35899
B8: Alejandra Olivares | C8: 1 | D8: 46030 | E8: Del 05 al 09 | F8: =IF(Rendiciones[[#This Row],[Fecha ]]<>"",TEXT(Rendiciones[[#This Row],[Fecha ]],"MMMM"),"") -> enero | G8: HG | H8: Oficina | I8: Artículos de Oficina | M8: 12620 | N8: =Rendiciones[[#This Row],[Monto Neto ]]*19% -> 0 | O8: =+Rendiciones[[#This Row],[Monto Neto ]]+Rendiciones[[#This Row],[Monto Exento ]]+Rendiciones[[#This Row],[Iva]] -> 12620 | P8: Banco Internacional HGI | Q8: 46031 | R8: 48519 | S8: =Rendiciones[[#This Row],[Total ]]-Rendiciones[[#This Row],[Monto ]] -> -35899
B9: Javier Salazar | C9: 1 | D9: 46030 | E9: Del 05 al 09 | F9: =IF(Rendiciones[[#This Row],[Fecha ]]<>"",TEXT(Rendiciones[[#This Row],[Fecha ]],"MMMM"),"") -> enero | G9: HGI. | H9: Operacionales | I9: Bodega | K9: Factura | L9: 12580 | N9: =Rendiciones[[#This Row],[Monto Neto ]]*19% -> 2390.2 | O9: =+Rendiciones[[#This Row],[Monto Neto ]]+Rendiciones[[#This Row],[Monto Exento ]]+Rendiciones[[#This Row],[Iva]] -> 14970.2 | S9: =Rendiciones[[#This Row],[Total ]]-Rendiciones[[#This Row],[Monto ]] -> 14970.2
B10: Javier Salazar | C10: 1 | D10: 46030 | E10: Del 05 al 09 | F10: =IF(Rendiciones[[#This Row],[Fecha ]]<>"",TEXT(Rendiciones[[#This Row],[Fecha ]],"MMMM"),"") -> enero | G10: HGI. | H10: Operacionales | I10: Bodega | K10: Factura | L10: 49588 | N10: =Rendiciones[[#This Row],[Monto Neto ]]*19% -> 9421.72 | O10: =+Rendiciones[[#This Row],[Monto Neto ]]+Rendiciones[[#This Row],[Monto Exento ]]+Rendiciones[[#This Row],[Iva]] -> 59009.72 | S10: =Rendiciones[[#This Row],[Total ]]-Rendiciones[[#This Row],[Monto ]] -> 59009.72
B11: Javier Salazar | C11: 1 | D11: 46030 | E11: Del 05 al 09 | F11: =IF(Rendiciones[[#This Row],[Fecha ]]<>"",TEXT(Rendiciones[[#This Row],[Fecha ]],"MMMM"),"") -> enero | G11: HGI. | H11: Operacionales | I11: Peajes / Estacionamientos | M11: 750 | N11: =Rendiciones[[#This Row],[Monto Neto ]]*19% -> 0 | O11: =+Rendiciones[[#This Row],[Monto Neto ]]+Rendiciones[[#This Row],[Monto Exento ]]+Rendiciones[[#This Row],[Iva]] -> 750 | S11: =Rendiciones[[#This Row],[Total ]]-Rendiciones[[#This Row],[Monto ]] -> 750
B12: Javier Salazar | C12: 1 | D12: 46030 | E12: Del 05 al 09 | F12: =IF(Rendiciones[[#This Row],[Fecha ]]<>"",TEXT(Rendiciones[[#This Row],[Fecha ]],"MMMM"),"") -> enero | G12: HGI. | H12: Operacionales | I12: Comidas y Bebidas | M12: 10000 | N12: =Rendiciones[[#This Row],[Monto Neto ]]*19% -> 0 | O12: =+Rendiciones[[#This Row],[Monto Neto ]]+Rendiciones[[#This Row],[Monto Exento ]]+Rendiciones[[#This Row],[Iva]] -> 10000 | P12: Banco Internacional HGI | Q12: 46031 | R12: 84729.92 | S12: =Rendiciones[[#This Row],[Total ]]-Rendiciones[[#This Row],[Monto ]] -> -74729.92
B13: David Herce | C13: 1 | D13: 46034 | E13: Del 12 al 16 | F13: =IF(Rendiciones[[#This Row],[Fecha ]]<>"",TEXT(Rendiciones[[#This Row],[Fecha ]],"MMMM"),"") -> enero | G13: O. PAÍS | H13: Activo fijo | I13: Equipos Electronicos y de Computacion | K13: Factura | L13: 588227 | N13: =Rendiciones[[#This Row],[Monto Neto ]]*19% -> 111763.13 | O13: =+Rendiciones[[#This Row],[Monto Neto ]]+Rendiciones[[#This Row],[Monto Exento ]]+Rendiciones[[#This Row],[Iva]] -> 699990.13 | P13: Banco Internacional HGI | Q13: 46037 | R13: 699990 | S13: =Rendiciones[[#This Row],[Total ]]-Rendiciones[[#This Row],[Monto ]] -> 0.13
B14: Alejandra Olivares | C14: 2 | D14: 46037 | E14: Del 12 al 16 | F14: =IF(Rendiciones[[#This Row],[Fecha ]]<>"",TEXT(Rendiciones[[#This Row],[Fecha ]],"MMMM"),"") -> enero | G14: HG | H14: Oficina | I14: Miscelaneos Administracion | M14: =22131+6990 -> 29121 | N14: =Rendiciones[[#This Row],[Monto Neto ]]*19% -> 0 | O14: =+Rendiciones[[#This Row],[Monto Neto ]]+Rendiciones[[#This Row],[Monto Exento ]]+Rendiciones[[#This Row],[Iva]] -> 29121 | S14: =Rendiciones[[#This Row],[Total ]]-Rendiciones[[#This Row],[Monto ]] -> 29121
B15: Alejandra Olivares | C15: 2 | D15: 46037 | E15: Del 12 al 16 | F15: =IF(Rendiciones[[#This Row],[Fecha ]]<>"",TEXT(Rendiciones[[#This Row],[Fecha ]],"MMMM"),"") -> enero | G15: HG | H15: Oficina | I15: Artículos de Aseo | M15: =5340+2590+12990 -> 20920 | N15: =Rendiciones[[#This Row],[Monto Neto ]]*19% -> 0 | O15: =+Rendiciones[[#This Row],[Monto Neto ]]+Rendiciones[[#This Row],[Monto Exento ]]+Rendiciones[[#This Row],[Iva]] -> 20920 | P15: Banco Internacional HGI | Q15: 46037 | R15: 50041 | S15: =Rendiciones[[#This Row],[Total ]]-Rendiciones[[#This Row],[Monto ]] -> -29121
B16: Javier Salazar | C16: 2 | D16: 46037 | E16: Del 12 al 16 | F16: =IF(Rendiciones[[#This Row],[Fecha ]]<>"",TEXT(Rendiciones[[#This Row],[Fecha ]],"MMMM"),"") -> enero | G16: HGI. | H16: Operacionales | I16: Bencina | K16: Factura | L16: 32318 | M16: =5236+4701+300 -> 10237 | N16: =Rendiciones[[#This Row],[Monto Neto ]]*19% -> 6140.42 | O16: =+Rendiciones[[#This Row],[Monto Neto ]]+Rendiciones[[#This Row],[Monto Exento ]]+Rendiciones[[#This Row],[Iva]] -> 48695.42 | S16: =Rendiciones[[#This Row],[Total ]]-Rendiciones[[#This Row],[Monto ]] -> 48695.42
B17: Javier Salazar | C17: 2 | D17: 46037 | E17: Del 12 al 16 | F17: =IF(Rendiciones[[#This Row],[Fecha ]]<>"",TEXT(Rendiciones[[#This Row],[Fecha ]],"MMMM"),"") -> enero | G17: HGI. | H17: Operacionales | I17: Reparaciones y remodelaciones | K17: Factura | L17: 230728 | N17: =Rendiciones[[#This Row],[Monto Neto ]]*19% -> 43838.32 | O17: =+Rendiciones[[#This Row],[Monto Neto ]]+Rendiciones[[#This Row],[Monto Exento ]]+Rendiciones[[#This Row],[Iva]] -> 274566.32 | S17: =Rendiciones[[#This Row],[Total ]]-Rendiciones[[#This Row],[Monto ]] -> 274566.32
B18: Javier Salazar | C18: 2 | D18: 46037 | E18: Del 12 al 16 | F18: =IF(Rendiciones[[#This Row],[Fecha ]]<>"",TEXT(Rendiciones[[#This Row],[Fecha ]],"MMMM"),"") -> enero | G18: HGI. | H18: Operacionales | I18: Reparaciones y remodelaciones | K18: Factura | L18: -95003.6 | N18: =Rendiciones[[#This Row],[Monto Neto ]]*19% -> -18050.684 | O18: =+Rendiciones[[#This Row],[Monto Neto ]]+Rendiciones[[#This Row],[Monto Exento ]]+Rendiciones[[#This Row],[Iva]] -> -113054.28 | S18: =Rendiciones[[#This Row],[Total ]]-Rendiciones[[#This Row],[Monto ]] -> -113054.28
B19: Javier Salazar | C19: 2 | D19: 46037 | E19: Del 12 al 16 | F19: =IF(Rendiciones[[#This Row],[Fecha ]]<>"",TEXT(Rendiciones[[#This Row],[Fecha ]],"MMMM"),"") -> enero | G19: HGI. | H19: Operacionales | I19: Peajes / Estacionamientos | M19: =1600+1350 -> 2950 | N19: =Rendiciones[[#This Row],[Monto Neto ]]*19% -> 0 | O19: =+Rendiciones[[#This Row],[Monto Neto ]]+Rendiciones[[#This Row],[Monto Exento ]]+Rendiciones[[#This Row],[Iva]] -> 2950 | S19: =Rendiciones[[#This Row],[Total ]]-Rendiciones[[#This Row],[Monto ]] -> 2950
B20: Javier Salazar | C20: 2 | D20: 46037 | E20: Del 12 al 16 | F20: =IF(Rendiciones[[#This Row],[Fecha ]]<>"",TEXT(Rendiciones[[#This Row],[Fecha ]],"MMMM"),"") -> enero | G20: HGI. | H20: Operacionales | I20: Comidas y Bebidas | M20: 15950 | N20: =Rendiciones[[#This Row],[Monto Neto ]]*19% -> 0 | O20: =+Rendiciones[[#This Row],[Monto Neto ]]+Rendiciones[[#This Row],[Monto Exento ]]+Rendiciones[[#This Row],[Iva]] -> 15950 | S20: =Rendiciones[[#This Row],[Total ]]-Rendiciones[[#This Row],[Monto ]] -> 15950
B21: Javier Salazar | C21: 2 | D21: 46037 | E21: Del 12 al 16 | F21: =IF(Rendiciones[[#This Row],[Fecha ]]<>"",TEXT(Rendiciones[[#This Row],[Fecha ]],"MMMM"),"") -> enero | G21: HGI. | H21: Operacionales | I21: Otros | M21: 1200 | N21: =Rendiciones[[#This Row],[Monto Neto ]]*19% -> 0 | O21: =+Rendiciones[[#This Row],[Monto Neto ]]+Rendiciones[[#This Row],[Monto Exento ]]+Rendiciones[[#This Row],[Iva]] -> 1200 | P21: Banco Internacional HGI | Q21: 46038 | R21: 343361 | S21: =Rendiciones[[#This Row],[Total ]]-Rendiciones[[#This Row],[Monto ]] -> -342161
B22: David Herce | C22: 2 | D22: 46038 | E22: Del 12 al 16 | F22: =IF(Rendiciones[[#This Row],[Fecha ]]<>"",TEXT(Rendiciones[[#This Row],[Fecha ]],"MMMM"),"") -> enero | G22: O. PAÍS | H22: Activo fijo | I22: Equipos Electronicos y de Computacion | K22: Factura | L22: 129395 | N22: =Rendiciones[[#This Row],[Monto Neto ]]*19% -> 24585.05 | O22: =+Rendiciones[[#This Row],[Monto Neto ]]+Rendiciones[[#This Row],[Monto Exento ]]+Rendiciones[[#This Row],[Iva]] -> 153980.05 | S22: =Rendiciones[[#This Row],[Total ]]-Rendiciones[[#This Row],[Monto ]] -> 153980.05
B23: David Herce | C23: 3 | D23: 46038 | E23: Del 12 al 16 | F23: =IF(Rendiciones[[#This Row],[Fecha ]]<>"",TEXT(Rendiciones[[#This Row],[Fecha ]],"MMMM"),"") -> enero | G23: HG | H23: Operacionales | I23: Bencina | K23: Factura | M23: 20000 | N23: =Rendiciones[[#This Row],[Monto Neto ]]*19% -> 0 | O23: =+Rendiciones[[#This Row],[Monto Neto ]]+Rendiciones[[#This Row],[Monto Exento ]]+Rendiciones[[#This Row],[Iva]] -> 20000 | S23: =Rendiciones[[#This Row],[Total ]]-Rendiciones[[#This Row],[Monto ]] -> 20000
B24: David Herce | C24: 3 | D24: 46038 | E24: Del 12 al 16 | F24: =IF(Rendiciones[[#This Row],[Fecha ]]<>"",TEXT(Rendiciones[[#This Row],[Fecha ]],"MMMM"),"") -> enero | G24: HG | H24: Operacionales | I24: Taxi - Uber | M24: 22722 | N24: =Rendiciones[[#This Row],[Monto Neto ]]*19% -> 0 | O24: =+Rendiciones[[#This Row],[Monto Neto ]]+Rendiciones[[#This Row],[Monto Exento ]]+Rendiciones[[#This Row],[Iva]] -> 22722 | S24: =Rendiciones[[#This Row],[Total ]]-Rendiciones[[#This Row],[Monto ]] -> 22722
B25: David Herce | C25: 4 | D25: 46038 | E25: Del 12 al 16 | F25: =IF(Rendiciones[[#This Row],[Fecha ]]<>"",TEXT(Rendiciones[[#This Row],[Fecha ]],"MMMM"),"") -> enero | G25: O. PAÍS | H25: Activo fijo | I25: Equipos Electronicos y de Computacion | K25: Factura | L25: 1428555 | N25: =Rendiciones[[#This Row],[Monto Neto ]]*19% -> 271425.45 | O25: =+Rendiciones[[#This Row],[Monto Neto ]]+Rendiciones[[#This Row],[Monto Exento ]]+Rendiciones[[#This Row],[Iva]] -> 1699980.4 | S25: =Rendiciones[[#This Row],[Total ]]-Rendiciones[[#This Row],[Monto ]] -> 1699980.4
B26: David Herce | C26: 4 | D26: 46038 | E26: Del 12 al 16 | F26: =IF(Rendiciones[[#This Row],[Fecha ]]<>"",TEXT(Rendiciones[[#This Row],[Fecha ]],"MMMM"),"") -> enero | G26: O. PAÍS | H26: Activo fijo | I26: Equipos Electronicos y de Computacion | K26: Factura | L26: 151243.5 | N26: =Rendiciones[[#This Row],[Monto Neto ]]*19% -> 28736.265 | O26: =+Rendiciones[[#This Row],[Monto Neto ]]+Rendiciones[[#This Row],[Monto Exento ]]+Rendiciones[[#This Row],[Iva]] -> 179979.77 | P26: Banco Internacional HGI | Q26: 46041 | R26: 2076662.4 | S26: =Rendiciones[[#This Row],[Total ]]-Rendiciones[[#This Row],[Monto ]] -> -1896682.6
B27: Raul Diaz | C27: 1 | D27: 46038 | E27: Del 12 al 16 | F27: =IF(Rendiciones[[#This Row],[Fecha ]]<>"",TEXT(Rendiciones[[#This Row],[Fecha ]],"MMMM"),"") -> enero | G27: HG | H27: Operacionales | I27: Bencina | K27: Factura | L27: 33915 | M27: =5439+4209 -> 9648 | N27: =Rendiciones[[#This Row],[Monto Neto ]]*19% -> 6443.85 | O27: =+Rendiciones[[#This Row],[Monto Neto ]]+Rendiciones[[#This Row],[Monto Exento ]]+Rendiciones[[#This Row],[Iva]] -> 50006.85 | S27: =Rendiciones[[#This Row],[Total ]]-Rendiciones[[#This Row],[Monto ]] -> 50006.85
B28: Raul Diaz | C28: 1 | D28: 46038 | E28: Del 12 al 16 | F28: =IF(Rendiciones[[#This Row],[Fecha ]]<>"",TEXT(Rendiciones[[#This Row],[Fecha ]],"MMMM"),"") -> enero | G28: HG | H28: Operacionales | I28: Bodega | K28: Factura | L28: 184831 | N28: =Rendiciones[[#This Row],[Monto Neto ]]*19% -> 35117.89 | O28: =+Rendiciones[[#This Row],[Monto Neto ]]+Rendiciones[[#This Row],[Monto Exento ]]+Rendiciones[[#This Row],[Iva]] -> 219948.89 | S28: =Rendiciones[[#This Row],[Total ]]-Rendiciones[[#This Row],[Monto ]] -> 219948.89
B29: Raul Diaz | C29: 1 | D29: 46038 | E29: Del 12 al 16 | F29: =IF(Rendiciones[[#This Row],[Fecha ]]<>"",TEXT(Rendiciones[[#This Row],[Fecha ]],"MMMM"),"") -> enero | G29: HG | H29: Operacionales | I29: Peajes / Estacionamientos | M29: =2950+400+470 -> 3820 | N29: =Rendiciones[[#This Row],[Monto Neto ]]*19% -> 0 | O29: =+Rendiciones[[#This Row],[Monto Neto ]]+Rendiciones[[#This Row],[Monto Exento ]]+Rendiciones[[#This Row],[Iva]] -> 3820 | S29: =Rendiciones[[#This Row],[Total ]]-Rendiciones[[#This Row],[Monto ]] -> 3820
B30: Raul Diaz | C30: 1 | D30: 46038 | E30: Del 12 al 16 | F30: =IF(Rendiciones[[#This Row],[Fecha ]]<>"",TEXT(Rendiciones[[#This Row],[Fecha ]],"MMMM"),"") -> enero | G30: HG | H30: Operacionales | I30: Otros | M30: =2700+3000 -> 5700 | N30: =Rendiciones[[#This Row],[Monto Neto ]]*19% -> 0 | O30: =+Rendiciones[[#This Row],[Monto Neto ]]+Rendiciones[[#This Row],[Monto Exento ]]+Rendiciones[[#This Row],[Iva]] -> 5700 | P30: No Genera Pago | S30: =Rendiciones[[#This Row],[Total ]]-Rendiciones[[#This Row],[Monto ]] -> 5700
B31: Javier Salazar | C31: 2 | D31: 46045 | E31: Del 19 al 23 | F31: =IF(Rendiciones[[#This Row],[Fecha ]]<>"",TEXT(Rendiciones[[#This Row],[Fecha ]],"MMMM"),"") -> enero | G31: HGI. | N31: =Rendiciones[[#This Row],[Monto Neto ]]*19% -> 0 | O31: =+Rendiciones[[#This Row],[Monto Neto ]]+Rendiciones[[#This Row],[Monto Exento ]]+Rendiciones[[#This Row],[Iva]] -> 0 | P31: Banco Internacional HGI | Q31: 46045 | R31: -113053.54 | S31: =Rendiciones[[#This Row],[Total ]]-Rendiciones[[#This Row],[Monto ]] -> 113053.54
B32: Alejandra Olivares | C32: 3 | D32: 46044 | E32: Del 19 al 23 | F32: =IF(Rendiciones[[#This Row],[Fecha ]]<>"",TEXT(Rendiciones[[#This Row],[Fecha ]],"MMMM"),"") -> enero | G32: HG | H32: Oficina | I32: Miscelaneos Administracion | M32: 27009 | N32: =Rendiciones[[#This Row],[Monto Neto ]]*19% -> 0 | O32: =+Rendiciones[[#This Row],[Monto Neto ]]+Rendiciones[[#This Row],[Monto Exento ]]+Rendiciones[[#This Row],[Iva]] -> 27009 | S32: =Rendiciones[[#This Row],[Total ]]-Rendiciones[[#This Row],[Monto ]] -> 27009
B33: Alejandra Olivares | C33: 3 | D33: 46044 | E33: Del 19 al 23 | F33: =IF(Rendiciones[[#This Row],[Fecha ]]<>"",TEXT(Rendiciones[[#This Row],[Fecha ]],"MMMM"),"") -> enero | G33: HG | H33: Oficina | I33: Envíos y encomiendas | M33: 11702 | N33: =Rendiciones[[#This Row],[Monto Neto ]]*19% -> 0 | O33: =+Rendiciones[[#This Row],[Monto Neto ]]+Rendiciones[[#This Row],[Monto Exento ]]+Rendiciones[[#This Row],[Iva]] -> 11702 | P33: Scotianbank CLP | Q33: 46045 | R33: 38711 | S33: =Rendiciones[[#This Row],[Total ]]-Rendiciones[[#This Row],[Monto ]] -> -27009
B34: Tomas Castro | C34: 1 | D34: 46043 | E34: Del 19 al 23 | F34: =IF(Rendiciones[[#This Row],[Fecha ]]<>"",TEXT(Rendiciones[[#This Row],[Fecha ]],"MMMM"),"") -> enero | G34: HG | H34: Operacionales | I34: Patente | M34: 1291352 | N34: =Rendiciones[[#This Row],[Monto Neto ]]*19% -> 0 | O34: =+Rendiciones[[#This Row],[Monto Neto ]]+Rendiciones[[#This Row],[Monto Exento ]]+Rendiciones[[#This Row],[Iva]] -> 1291352 | P34: Banco Internacional HGI | Q34: 46043 | R34: 1291352 | S34: =Rendiciones[[#This Row],[Total ]]-Rendiciones[[#This Row],[Monto ]] -> 0
B35: Tomas Castro | C35: 1 | D35: 46043 | E35: Del 19 al 23 | F35: =IF(Rendiciones[[#This Row],[Fecha ]]<>"",TEXT(Rendiciones[[#This Row],[Fecha ]],"MMMM"),"") -> enero | G35: HG | H35: Operacionales | I35: Patente | M35: 1243599 | N35: =Rendiciones[[#This Row],[Monto Neto ]]*19% -> 0 | O35: =+Rendiciones[[#This Row],[Monto Neto ]]+Rendiciones[[#This Row],[Monto Exento ]]+Rendiciones[[#This Row],[Iva]] -> 1243599 | P35: Scotianbank CLP | Q35: 46045 | R35: 500000 | S35: =Rendiciones[[#This Row],[Total ]]-Rendiciones[[#This Row],[Monto ]] -> 743599
B36: Edgar hernandez | C36: 1 | D36: 46041 | E36: Del 19 al 23 | F36: =IF(Rendiciones[[#This Row],[Fecha ]]<>"",TEXT(Rendiciones[[#This Row],[Fecha ]],"MMMM"),"") -> enero | G36: HG | H36: Extras | I36: Bencina | K36: Factura | L36: 13544 | M36: =2189+1694 -> 3883 | N36: =Rendiciones[[#This Row],[Monto Neto ]]*19% -> 2573.36 | O36: =+Rendiciones[[#This Row],[Monto Neto ]]+Rendiciones[[#This Row],[Monto Exento ]]+Rendiciones[[#This Row],[Iva]] -> 20000.36 | S36: =Rendiciones[[#This Row],[Total ]]-Rendiciones[[#This Row],[Monto ]] -> 20000.36
B37: Edgar hernandez | C37: 1 | D37: 46041 | E37: Del 19 al 23 | F37: =IF(Rendiciones[[#This Row],[Fecha ]]<>"",TEXT(Rendiciones[[#This Row],[Fecha ]],"MMMM"),"") -> enero | G37: HG | H37: Extras | I37: Bencina | K37: Factura | L37: 28029 | M37: =4489+3474 -> 7963 | N37: =Rendiciones[[#This Row],[Monto Neto ]]*19% -> 5325.51 | O37: =+Rendiciones[[#This Row],[Monto Neto ]]+Rendiciones[[#This Row],[Monto Exento ]]+Rendiciones[[#This Row],[Iva]] -> 41317.51 | S37: =Rendiciones[[#This Row],[Total ]]-Rendiciones[[#This Row],[Monto ]] -> 41317.51
B38: Edgar hernandez | C38: 1 | D38: 46041 | E38: Del 19 al 23 | F38: =IF(Rendiciones[[#This Row],[Fecha ]]<>"",TEXT(Rendiciones[[#This Row],[Fecha ]],"MMMM"),"") -> enero | G38: HG | H38: Extras | I38: Bencina | K38: Factura | L38: 24329 | M38: =3973+3075+500 -> 7548 | N38: =Rendiciones[[#This Row],[Monto Neto ]]*19% -> 4622.51 | O38: =+Rendiciones[[#This Row],[Monto Neto ]]+Rendiciones[[#This Row],[Monto Exento ]]+Rendiciones[[#This Row],[Iva]] -> 36499.51 | S38: =Rendiciones[[#This Row],[Total ]]-Rendiciones[[#This Row],[Monto ]] -> 36499.51
B39: Edgar hernandez | C39: 1 | D39: 46041 | E39: Del 19 al 23 | F39: =IF(Rendiciones[[#This Row],[Fecha ]]<>"",TEXT(Rendiciones[[#This Row],[Fecha ]],"MMMM"),"") -> enero | G39: HG | H39: Extras | I39: Bencina | K39: Factura | L39: 22588 | M39: =3753+3369+500 -> 7622 | N39: =Rendiciones[[#This Row],[Monto Neto ]]*19% -> 4291.72 | O39: =+Rendiciones[[#This Row],[Monto Neto ]]+Rendiciones[[#This Row],[Monto Exento ]]+Rendiciones[[#This Row],[Iva]] -> 34501.72 | S39: =Rendiciones[[#This Row],[Total ]]-Rendiciones[[#This Row],[Monto ]] -> 34501.72
B40: Edgar hernandez | C40: 1 | D40: 46041 | E40: Del 19 al 23 | F40: =IF(Rendiciones[[#This Row],[Fecha ]]<>"",TEXT(Rendiciones[[#This Row],[Fecha ]],"MMMM"),"") -> enero | G40: HG | H40: Extras | I40: Bencina | K40: Factura | L40: 23930 | M40: =3975+3569+500 -> 8044 | N40: =Rendiciones[[#This Row],[Monto Neto ]]*19% -> 4546.7 | O40: =+Rendiciones[[#This Row],[Monto Neto ]]+Rendiciones[[#This Row],[Monto Exento ]]+Rendiciones[[#This Row],[Iva]] -> 36520.7 | S40: =Rendiciones[[#This Row],[Total ]]-Rendiciones[[#This Row],[Monto ]] -> 36520.7
B41: Edgar hernandez | C41: 1 | D41: 46041 | E41: Del 19 al 23 | F41: =IF(Rendiciones[[#This Row],[Fecha ]]<>"",TEXT(Rendiciones[[#This Row],[Fecha ]],"MMMM"),"") -> enero | G41: HG | H41: Oficina | I41: Artículos de Oficina | M41: 9819 | N41: =Rendiciones[[#This Row],[Monto Neto ]]*19% -> 0 | O41: =+Rendiciones[[#This Row],[Monto Neto ]]+Rendiciones[[#This Row],[Monto Exento ]]+Rendiciones[[#This Row],[Iva]] -> 9819 | S41: =Rendiciones[[#This Row],[Total ]]-Rendiciones[[#This Row],[Monto ]] -> 9819
B42: Edgar hernandez | C42: 1 | D42: 46041 | E42: Del 19 al 23 | F42: =IF(Rendiciones[[#This Row],[Fecha ]]<>"",TEXT(Rendiciones[[#This Row],[Fecha ]],"MMMM"),"") -> enero | G42: HG | H42: Extras | I42: Comidas y Bebidas | M42: =5500+6069+2740+3800+4605+5340.4 -> 28054.4 | N42: =Rendiciones[[#This Row],[Monto Neto ]]*19% -> 0 | O42: =+Rendiciones[[#This Row],[Monto Neto ]]+Rendiciones[[#This Row],[Monto Exento ]]+Rendiciones[[#This Row],[Iva]] -> 28054.4 | S42: =Rendiciones[[#This Row],[Total ]]-Rendiciones[[#This Row],[Monto ]] -> 28054.4
...

Sheet Listas
K2: Q1 23 | L2: Q2 23 | M2: Q3 23 | N2: Q4 23
B3: Nombre del Solicitante | D3: C.C. | E3: Cuentas | F3: Subcuentas | G3: Rut Empresa | H3: Empresa | I3: Pagado Por
B4: David Herce | D4: HG | E4: Oficina | F4: Notario y Legal | G4: 76723245-4 | H4: Heca Global SPA | I4: Banco Estado HGI
B5: Manuel Guajardo | D5: HC | E5: Operacionales | F5: Miscelaneos Administracion | G5: 76886693-7 | H5: Hecaglobal Instruments SPA | I5: Banco Internacional HGI | P5: Gastos de Oficina
B6: Tomas Castro | D6: HGI. | E6: Siga Sonriendo | F6: Equipos de Protección personal | G6: 77422425-4 | H6: Siga Sonriendo SPA | I6: No Genera Pago | P6: Gastos Operacionales
B7: Alvaro Martínez | D7: SS | E7: Viajes | F7: Otros Gastos de Oficina | G7: 77219167-7 | H7: Sonrie Pro Financial SPA | I7: Cash USD | P7: Gastos de Viaje
B8: Adolfo Quintana | D8: CS | E8: Extras | F8: Reparaciones y remodelaciones | I8: Cash CLP | P8: Siga Sonriendo
B9: Alejandra Olivares | D9: MIXTO | E9: Otros | F9: Artículos de Aseo | I9: Scotianbank CLP | P9: Gastos Financieros
B10: Davis Torres | D10: O. PAÍS | E10: Marketing | F10: Artículos de Oficina | P10: Gastos de Personal
B11: David Herce | D11: C. ORDEN | E11: Gastos de Personal | F11: Bencina | P11: Gastos de Marketing y Publicidad
B12: Rodrigo Letelier | D12: Air Heca | E12: Importaciones / Export. | F12: Estacionamiento | P12: Gastos Extras
B13: Fernando Stange | E13: Activo fijo | F13: TAG | P13: Gastos Tax Ingenieria
B14: Dailin Arellano | E14: Impuestos | F14: Bus- Peaje
B15: ALG | F15: Taxi - Uber
B16: Teresa Espinoza | F16: Metro - tarjeta Bip
B17: Mariangel Veloz | F17: Comidas y Bebidas
B18: Raul Diaz | F18: Gastos Furgón
B19: Javier Salazar | F19: Gastos Auto
B20: Brigitte Moran Mesa | F20: Gastos Varios
B21: Ana Jocelyn Schnell | F21: Maletas Pelican
B22: Arleen Cedeño | F22: Peoneta - Yale
B23: Deisy Sierra | F23: Comisiones Bancarias
B24: Nicolas Gonzalez | F24: Teléfono celular
B25: Edgar hernandez | F25: Estacionamiento Ofic. 25
B26: Abel Kottwitz | F26: Envíos y encomiendas
... B30: Edynar Monsalbe | F30: Gastos de Ambulancia
F31: Peajes / Estacionamientos
F32: Hospedaje
F33: Combustible
F34: Pasajes Bus - Aéreos
F35: Gastos Argentina
F36: Pagos Cristóbal
F37: Gastos Otros Países - Chile
F38: Autopistas CS / Heca SA
F39: Pasajes Aéreos CS
F40: Otros
F41: Almacenaje Importaciones
F42: DIN Importaciones
... F65: Gastos de Vehiculo

Sheet 2024 & 2023 & 2022
B2: COMPARATIVO DE GASTOS
B3: HECA - CHILE
B7: Variacion 2024 | C7: =+C19/GETPIVOTDATA("Cuarter 1 ",$B$25)-1 -> #REF! | D7: =+D19/GETPIVOTDATA("Cuarter 2 ",$B$25)-1 -> #REF! | E7: =+E19/GETPIVOTDATA("Cuarter 3 ",$B$25)-1 -> #REF! | F7: =+F19/GETPIVOTDATA("Cuarter 4 ",$B$25)-1 -> #REF!
B8: 2024
B9: Chile 2024 | C9: Cuarter 1 | D9: Cuarter 2 | E9: Cuarter 3 | F9: Cuarter 4 | I9: Chile | J9: Cuarter 1 | K9: Cuarter 2 | L9: Cuarter 3 | M9: Cuarter 4 | N9: total
B10: Gastos de Oficina | C10: =+GETPIVOTDATA("Monto ",'[1]TD Cuarter'!$B$5,"Cuenta","Gastos de Oficina ") -> #REF! | D10: =+GETPIVOTDATA("Monto ",'[1]TD Cuarter'!$S$5,"Cuenta","Gastos de Oficina ") -> #REF! | E10: =+GETPIVOTDATA("Monto ",'[1]TD Cuarter'!$AG$5,"Cuenta","Gastos de Oficina ") -> #REF! | F10: =+GETPIVOTDATA("Monto ",'[1]TD Cuarter'!$AN$5,"Cuenta","Gastos de Oficina ") -> #REF! | I10: 2024 | J10: =+C19 -> #REF! | K10: =+D19 -> #REF! | L10: =+E19 -> #REF! | M10: =+F19 -> #REF! | N10: =SUM(J10:M10) -> #REF! | O10: =+N10/N11-1 -> #REF! | P10: =+N10/N12-1 -> #REF!
B11: Gastos Operacionales | C11: =+GETPIVOTDATA("Monto ",'[1]TD Cuarter'!$B$5,"Cuenta","Gastos Operacionales ") -> #REF! | D11: =+GETPIVOTDATA("Monto ",'[1]TD Cuarter'!$S$5,"Cuenta","Gastos Operacionales ") -> #REF! | E11: =+GETPIVOTDATA("Monto ",'[1]TD Cuarter'!$AG$5,"Cuenta","Gastos Operacionales ") -> #REF! | F11: =+GETPIVOTDATA("Monto ",'[1]TD Cuarter'!$AN$5,"Cuenta","Gastos Operacionales ") -> #REF! | I11: 2023 | J11: =+GETPIVOTDATA("Cuarter 1 ",$B$25) -> 2.9372403e+08 | K11: =+GETPIVOTDATA("Cuarter 2 ",$B$25) -> 3.2537824e+08 | L11: =+GETPIVOTDATA("Cuarter 3 ",$B$25) -> 3.1624304e+08 | M11: =+GETPIVOTDATA("Cuarter 4 ",$B$25) -> 3.069793e+08 | N11: =SUM(J11:M11) -> 1.2423246e+09 | O11: =+N11/N12-1 -> 0.072363845
B12: Gastos de Viaje | C12: 0 | D12: =+GETPIVOTDATA("Monto ",'[1]TD Cuarter'!$S$5,"Cuenta","Gastos de Viaje ") -> #REF! | E12: =+GETPIVOTDATA("Monto ",'[1]TD Cuarter'!$AG$5,"Cuenta","Gastos de Viaje ") -> #REF! | F12: 0 | I12: 2022 | J12: =+GETPIVOTDATA("Cuarter 1 ",$B$40) -> 2.6838081e+08 | K12: =+GETPIVOTDATA("Cuarter 2 ",$B$40) -> 3.1617478e+08 | L12: =+GETPIVOTDATA("Cuarter 3 ",$B$40) -> 2.392393e+08 | M12: =+GETPIVOTDATA(" cuarter 4",$B$40) -> 3.3469682e+08 | N12: =SUM(J12:M12) -> 1.1584917e+09
B13: Siga Sonriendo | C13: =+GETPIVOTDATA("Monto ",'[1]TD Cuarter'!$B$5,"Cuenta","Siga Sonriendo ") -> #REF! | D13: =+GETPIVOTDATA("Monto ",'[1]TD Cuarter'!$S$5,"Cuenta","Siga Sonriendo ") -> #REF! | E13: =+GETPIVOTDATA("Monto ",'[1]TD Cuarter'!$AG$5,"Cuenta","Siga Sonriendo ") -> #REF! | F13: =+GETPIVOTDATA("Monto ",'[1]TD Cuarter'!$AN$5,"Cuenta","Siga Sonriendo ") -> #REF!
B14: Gastos Financieros | C14: =+GETPIVOTDATA("Monto ",'[1]TD Cuarter'!$B$5,"Cuenta","Gastos Financieros") -> #REF! | D14: =+GETPIVOTDATA("Monto ",'[1]TD Cuarter'!$S$5,"Cuenta","Gastos Financieros") -> #REF! | E14: =+GETPIVOTDATA("Monto ",'[1]TD Cuarter'!$AG$5,"Cuenta","Gastos Financieros") -> #REF! | F14: =+GETPIVOTDATA("Monto ",'[1]TD Cuarter'!$AN$5,"Cuenta","Gastos Financieros") -> #REF!
B15: Gastos de Personal | C15: =+GETPIVOTDATA("Monto ",'[1]TD Cuarter'!$B$5,"Cuenta","Gastos de Personal ") -> #REF! | D15: =+GETPIVOTDATA("Monto ",'[1]TD Cuarter'!$S$5,"Cuenta","Gastos de Personal ") -> #REF! | E15: =+GETPIVOTDATA("Monto ",'[1]TD Cuarter'!$AG$5,"Cuenta","Gastos de Personal ") -> #REF! | F15: =+GETPIVOTDATA("Monto ",'[1]TD Cuarter'!$AN$5,"Cuenta","Gastos de Personal ") -> #REF!
B16: Gastos de Marketing y Publicidad | C16: =+GETPIVOTDATA("Monto ",'[1]TD Cuarter'!$B$5,"Cuenta","Gastos de Marketing y Publicidad ") -> #REF! | D16: =+GETPIVOTDATA("Monto ",'[1]TD Cuarter'!$S$5,"Cuenta","Gastos de Marketing y Publicidad ") -> #REF! | E16: =+GETPIVOTDATA("Monto ",'[1]TD Cuarter'!$AG$5,"Cuenta","Gastos de Marketing y Publicidad ") -> #REF! | F16: 0 | I16: Realizando un analisis comparativo de gastos del año 2024 con 2023, hubo una disminucion del
B17: Gastos Extras | I17: =+O10 -> #REF! | J17: en el periodo
B18: Gastos Tax Ingenieria | C18: =+GETPIVOTDATA("Monto ",'[1]TD Cuarter'!$B$5,"Cuenta","Gastos Tax Ingenieria ") -> #REF! | D18: =+GETPIVOTDATA("Monto ",'[1]TD Cuarter'!$S$5,"Cuenta","Gastos Tax Ingenieria ") -> #REF! | E18: =+GETPIVOTDATA("Monto ",'[1]TD Cuarter'!$AG$5,"Cuenta","Gastos Tax Ingenieria ") -> #REF! | F18: =+GETPIVOTDATA("Monto ",'[1]TD Cuarter'!$AN$5,"Cuenta","Gastos Tax Ingenieria ") -> #REF!
B19: Total general | C19: =SUM(C10:C18) -> #REF! | D19: =SUM(D10:D18) -> #REF! | E19: =SUM(E10:E18) -> #REF! | F19: =SUM(F10:F18) -> #REF! | I19: De igual forma, el 2024 con respecto al 2022 tuvo un crecimiento en los gastos del
I20: =+P10 -> #REF! | J20: en el mismo periodo.
B21: Variacion trimestral | C21: =+C19/GETPIVOTDATA("Cuarter 4 ",$B$25)-1 -> #REF! | D21: =+D19/C19-1 -> #REF! | E21: =+E19/D19-1 -> #REF! | F21: =+F19/E19-1 -> #REF!
B24: 2023
B25: Chile 2023 | C25: Cuarter 1 | D25: Cuarter 2 | E25: Cuarter 3 | F25: Cuarter 4
B26: Gastos de Oficina | C26: 25923832 | D26: 31550235 | E26: 37764132 | F26: 34622950
B27: Gastos de Operaciones | C27: 57771765 | D27: 60692034 | E27: 58744192 | F27: 47009437
B28: Gastos de Viaje | C28: 557138 | D28: 3849235 | E28: 1447983 | F28: 548602
B29: Siga Sonriendo | C29: 9799265 | D29: 4404905 | E29: 4094372 | F29: 4415570
B30: Gastos Financieros | C30: 58632692 | D30: 74596765 | E30: 69111531 | F30: 76094471
B31: Gastos de Personal | C31: 1.0576383e+08 | D31: 1.0843186e+08 | E31: 1.0484164e+08 | F31: 1.0202148e+08
B32: Gasto Tax Ingenieria | C32: 35275515 | D32: 41853206 | E32: 40239181 | F32: 42266791
B33: Total general | C33: 2.9372403e+08 | D33: 3.2537824e+08 | E33: 3.1624304e+08 | F33: 3.069793e+08
B36: Variacion trimestral | C36: =GETPIVOTDATA("Cuarter 1 ",$B$25)/GETPIVOTDATA(" cuarter 4",$B$40)-1 -> -0.12241761 | D36: =GETPIVOTDATA("Cuarter 2 ",$B$25)/GETPIVOTDATA("Cuarter 1 ",$B$25)-1 -> 0.10776854 | E36: =GETPIVOTDATA("Cuarter 3 ",$B$25)/GETPIVOTDATA("Cuarter 2 ",$B$25)-1 -> -0.028075653 | F36: =GETPIVOTDATA("Cuarter 4 ",$B$25)/GETPIVOTDATA("Cuarter 3 ",$B$25)-1 -> -0.029293085
B39: 2022
B40: Chile 2022 | C40: Cuarter 1 | D40: Cuarter 2 | E40: Cuarter 3 | F40: cuarter 4
B41: Gastos de Oficina | C41: 31878058 | D41: 41617780 | E41: 28667274 | F41: 32296786
B42: Gastos de Operaciones | C42: 18498122 | D42: 32614841 | E42: 31407638 | F42: 41457713
B43: Gastos de Viaje | C43: 589436 | D43: 911167 | E43: 668827 | F43: 247775
B44: Siga Sonriendo | C44: 46073406 | D44: 59560197 | E44: 36824033 | F44: 40349454
B45: Gastos Financieros | C45: 41949615 | D45: 53043142 | E45: 45504378 | F45: 70146271
B46: Gastos de Personal | C46: 91520005 | D46: 85141216 | E46: 66117646 | F46: 1.0775891e+08
B47: Gasto Tax Ingenieria | C47: 37872163 | D47: 43286435 | E47: 30049505 | F47: 42439903
B48: Total general | C48: 2.6838081e+08 | D48: 3.1617478e+08 | E48: 2.392393e+08 | F48: 3.3469682e+08
B51: Variacion trimestral | D51: =GETPIVOTDATA("Cuarter 2 ",$B$40)/GETPIVOTDATA("Cuarter 1 ",$B$40)-1 -> 0.17808267 | E51: =+GETPIVOTDATA("Cuarter 3 ",$B$40)/GETPIVOTDATA("Cuarter 2 ",$B$40)-1 -> -0.24333211 | F51: =GETPIVOTDATA(" cuarter 4",$B$40)/GETPIVOTDATA("Cuarter 3 ",$B$40)-1 -> 0.39900432
B53: ****No incluyen los gastos Extras

Sheet 2024&2023& 2022 G. Extra
B2: COMPARATIVO DE GASTOS
B3: HECA - CHILE
I4: Chile | J4: Cuarter 1 | K4: Cuarter 2 | L4: Cuarter 3 | M4: Cuarter 4 | N4: total
I5: 2025 | J5: =+C18 -> 39542991 | K5: =+D18 -> 59196948 | L5: =+E18 -> 63513736 | M5: =+F18 -> 0 | N5: =SUM(J5:K5) -> 98739939
B6: Variacion 2025 | C6: =+C18/C34-1 -> -0.91731827 | D6: =+D18/D34-1 -> -0.88214896 | E6: =+E18/E34-1 -> -0.83120136 | F6: =+F18/F34-1 -> -1 | I6: 2024 | J6: =+C34 -> 4.7825548e+08 | K6: =+D34 -> 5.0230314e+08 | L6: =+E34 -> 3.7626924e+08 | M6: =+F34 -> 5.5667411e+08 | N6: =SUM(J6:K6) -> 9.8055862e+08 | O6: =+N5/N6-1 -> -0.89930236
B7: 2025 | I7: 2023 | J7: =+GETPIVOTDATA("Cuarter 1 ",$B$40) -> 6.1428645e+08 | K7: =+GETPIVOTDATA("Cuarter 2 ",$B$40) -> 5.8766595e+08 | L7: =+GETPIVOTDATA("Cuarter 3 ",$B$40) -> 5.9067415e+08 | M7: =+GETPIVOTDATA("Cuarter 4 ",$B$40) -> 6.3477983e+08 | N7: =SUM(J7:K7) -> 1.2019524e+09 | O7: =+N5/N7-1 -> -0.91785037
B8: Chile 2024 | C8: Cuarter 1 | D8: Cuarter 2 | E8: Cuarter 3 | F8: Cuarter 4 | I8: 2022 | J8: =+GETPIVOTDATA("Cuarter 1 ",$B$55) -> 4.1405747e+08 | K8: =+GETPIVOTDATA("Cuarter 2 ",$B$55) -> 4.6008915e+08 | L8: =+GETPIVOTDATA("Cuarter 3 ",$B$55) -> 3.5225972e+08 | M8: =+GETPIVOTDATA(" cuarter 4",$B$55) -> 5.5706748e+08 | N8: =SUM(J8:K8) -> 8.7414662e+08 | O8: =+N5/N8-1 -> -0.88704419
B9: Gastos de Oficina | C9: =SUM([2]TD!$C$8:$E$8) -> 39542991 | D9: =SUM([2]TD!$F$8:$H$8) -> 59196948 | E9: =SUM([2]TD!$I$8:$K$8) -> 63513736
B10: Gastos Operacionales | C10: =SUM([2]TD!$C$24:$E$24) -> 0 | D10: =SUM([2]TD!$F$24:$H$24) -> 0 | E10: =SUM([2]TD!$I$24:$K$24) -> 0 | I10: Realizando un analisis comparativo de gastos del año 2025 con años anteriores, hubo una disminucion del
B11: Gastos de Viaje | I11: =+O6 -> -0.89930236 | J11: durante el 1er semestre del año
B12: Siga Sonriendo | C12: =SUM([2]TD!$C$37:$E$37) -> 0 | D12: =SUM([2]TD!$F$37:$H$37) -> 0 | E12: =SUM([2]TD!$I$37:$K$37) -> 0
B13: Gastos Financieros | C13: =SUM([2]TD!$C$83:$E$83) -> 0 | D13: =SUM([2]TD!$F$83:$H$83) -> 0 | E13: =SUM([2]TD!$I$83:$K$83) -> 0
B14: Gastos de Personal | C14: =SUM([2]TD!$C$77:$E$77) -> 0 | D14: =SUM([2]TD!$F$77:$H$77) -> 0
B15: Gastos de Marketing y Publicidad
B16: Gastos Extras | C16: =SUM([2]TD!$C$65:$E$65,[2]TD!$C$45:$E$45) -> 0 | D16: =SUM([2]TD!$F$45:$H$45,[2]TD!$F$65:$H$65) -> 0
B17: Gastos Tax Ingenieria | C17: =SUM([2]TD!$C$95:$E$95) -> 0 | D17: =SUM([2]TD!$F$95:$H$95) -> 0
B18: Total general | C18: =SUM(C9:C17) -> 39542991 | D18: =SUM(D9:D17) -> 59196948 | E18: =SUM(E9:E17) -> 63513736 | F18: =SUM(F9:F17) -> 0
B20: Variacion trimestral | C20: =+C18/C34-1 -> -0.91731827 | D20: =+D18/D34/-1 -> -0.11785104 | E20: =+E18/E34/-1 -> -0.16879864 | F20: =+F18/F34/-1 -> 0
B23: 2024
B24: Chile 2024 | C24: Cuarter 1 | D24: Cuarter 2 | E24: Cuarter 3 | F24: Cuarter 4
B25: Gastos de Oficina | C25: 27503870 | D25: 27152063 | E25: 22234572 | F25: 23639180
B26: Gastos Operacionales | C26: 38326905 | D26: 35888514 | E26: 35582526 | F26: 36454116
B27: Gastos de Viaje | C27: 0 | D27: 275428 | E27: 12000 | F27: 0
B28: Siga Sonriendo | C28: 4359326 | D28: 4318237 | E28: 4346056 | F28: 4463227
B29: Gastos Financieros | C29: 53158374 | D29: 54585023 | E29: 43700189 | F29: 39983421
B30: Gastos de Personal | C30: 96773224 | D30: 1.0199314e+08 | E30: 1.1486347e+08 | F30: 1.0210948e+08
B31: Gastos de Marketing y Publicidad | C31: 10326030 | D31: 375000 | E31: 1088820 | F31: 0
B32: Gastos Extras | C32: 2.2236596e+08 | D32: 2.629553e+08 | E32: 1.4469883e+08 | F32: 3.4451789e+08
B33: Gastos Tax Ingenieria | C33: 25441796 | D33: 14760439 | E33: 9742776 | F33: 5506789
B34: Total general | C34: =SUM(C25:C33) -> 4.7825548e+08 | D34: =SUM(D25:D33) -> 5.0230314e+08 | E34: =SUM(E25:E33) -> 3.7626924e+08 | F34: =SUM(F25:F33) -> 5.5667411e+08
B36: Variacion trimestral | C36: =+C34/GETPIVOTDATA("Cuarter 4 ",$B$40)-1 -> -0.24658053 | D36: =+D34/C34-1 -> 0.050282027 | E36: =+E34/D34-1 -> -0.25091202 | F36: =+F34/E34-1 -> 0.47945686
B39: 2023
B40: Chile 2023 | C40: Cuarter 1 | D40: Cuarter 2 | E40: Cuarter 3 | F40: Cuarter 4
B41: Gastos de Oficina | C41: 25923832 | D41: 31550235 | E41: 37764132 | F41: 34622950
B42: Gastos de Operaciones | C42: 57771765 | D42: 60692034 | E42: 58744192 | F42: 47009437
B43: Gastos de Viaje | C43: 557138 | D43: 3849235 | E43: 1447983 | F43: 548602
B44: Siga Sonriendo | C44: 9799265 | D44: 4404905 | E44: 4094372 | F44: 4415570
B45: Gastos Financieros | C45: 58632692 | D45: 74596765 | E45: 69111531 | F45: 76094471
B46: Gastos de Personal | C46: 1.0576383e+08 | D46: 1.0843186e+08 | E46: 1.0484164e+08 | F46: 1.0202148e+08
B47: Gastos Extras | C47: 3.2056242e+08 | D47: 2.6228771e+08 | E47: 2.7443112e+08 | F47: 3.2780053e+08
...

Sheet Detalle anual Gastos 
B2: Detalle trimestral de Gastos
B3: 2022-2025 | N3: Datos Acumulados
N4: Año | O4: Detalle | P4: Monto | Q4: Cuarter
A5: Tipo de gastos | N5: 2022 | O5: Gastos de Oficina | P5: 31878058 | Q5: Cuarter 1
A6: Gastos Operacionales | N6: 2022 | O6: Gastos Operacionales | P6: 18498122 | Q6: Cuarter 1
N7: 2022 | O7: Gastos de Viaje | P7: 589436 | Q7: Cuarter 1
B8: Chile | C8: Cuarter 1 | E8: Cuarter 2 | G8: Cuarter 3 | I8: Cuarter 4 | K8: total | L8: Parcial | N8: 2022 | O8: Siga Sonriendo | P8: 46073406 | Q8: Cuarter 1 | Y8: Suma de Monto | Z8: Etiquetas de columna
B9: 2025 | C9: =SUMIFS(P5:P122,O5:O122,A6,Q5:Q122,"Cuarter 1",Tabla4[Año],"2025") -> 0 | D9: =+C9/C10-1 -> -1 | E9: =SUMIFS(P5:P122,O5:O122,A6,Q5:Q122,"Cuarter 2",Tabla4[Año],"2025") -> 0 | F9: =+E9/E10-1 -> -1 | G9: =SUMIFS(P5:P122,O5:O122,A6,Q5:Q122,"Cuarter 3",Tabla4[Año],"2025") -> 0 | I9: =SUMIFS(P6:P123,O5:O122,A6,Q5:Q122,"Cuarter 4",Tabla4[Año],"2025") -> 0 | K9: =SUM(C9,E9,G9,I9) -> 0 | L9: =SUM(C9,E9) -> 0 | M9: =+L9/L10-1 -> -1 | N9: 2022 | O9: Gastos Financieros | P9: 41949615 | Q9: Cuarter 1 | Z9: Gastos Financieros | AD9: Total Gastos Financieros | AE9: Total general
B10: 2024 | C10: =SUMIFS(P5:P122,O5:O122,A6,Q5:Q122,"Cuarter 1",Tabla4[Año],"2024") -> 38326905 | E10: =SUMIFS(P5:P122,O5:O122,A6,Q5:Q122,"Cuarter 2",Tabla4[Año],"2024") -> 35888514 | G10: =SUMIFS(P5:P122,O5:O122,A6,Q5:Q122,"Cuarter 3",Tabla4[Año],"2024") -> 35582526 | I10: =SUMIFS(P5:P122,O5:O122,A6,Q5:Q122,"Cuarter 4",Tabla4[Año],"2024") -> 36454116 | K10: =SUM(C10,E10,G10,I10) -> 1.4625206e+08 | L10: =SUM(C10,E10) -> 74215418 | N10: 2022 | O10: Gastos de Personal | P10: 91520005 | Q10: Cuarter 1 | Y10: Etiquetas de fila | Z10: 2022 | AA10: 2023 | AB10: 2024 | AC10: 2025
B11: 2023 | C11: =SUMIFS(P5:P122,O5:O122,A6,Q5:Q122,"Cuarter 1",Tabla4[Año],"2023") -> 57771765 | D11: =+C10/C11-1 -> -0.33658069 | E11: =SUMIFS(P5:P122,O5:O122,A6,Q5:Q122,"Cuarter 2",Tabla4[Año],"2023") -> 60692034 | F11: =+E10/E11-1 -> -0.40867835 | G11: =SUMIFS(P5:P122,O5:O122,A6,Q5:Q122,"Cuarter 3",Tabla4[Año],"2023") -> 58744192 | H11: =+G10/G11-1 -> -0.3942801 | I11: =SUMIFS(P5:P122,O5:O122,A6,Q5:Q122,"Cuarter 4",Tabla4[Año],"2023") -> 47009437 | J11: =+I10/I11-1 -> -0.22453621 | K11: =SUM(C11,E11,G11,I11) -> 2.2421743e+08 | L11: =SUM(C11,E11) -> 118463799 | M11: =+L10/L11-1 -> -0.37351817 | N11: 2022 | O11: Gastos Extras | P11: 1.4567666e+08 | Q11: Cuarter 1 | Y11: Cuarter 1 | Z11: 41949615 | AA11: 58632692 | AB11: 53158374 | AC11: 0 | AD11: 153740681 | AE11: 153740681
B12: 2022 | C12: =SUMIFS(P5:P122,O5:O122,A6,Q5:Q122,"Cuarter 1",Tabla4[Año],"2022") -> 18498122 | E12: =SUMIFS(P5:P122,O5:O122,A6,Q5:Q122,"Cuarter 2",Tabla4[Año],"2022") -> 32614841 | G12: =SUMIFS(P5:P122,O5:O122,A6,Q5:Q122,"Cuarter 3",Tabla4[Año],"2022") -> 31407638 | I12: =SUMIFS(P5:P122,O5:O122,A6,Q5:Q122,"Cuarter 4",Tabla4[Año],"2022") -> 41457713 | K12: =SUM(C12,E12,G12,I12) -> 123978314 | L12: =SUM(C12,E12) -> 51112963 | N12: 2022 | O12: Gastos Tax Ingenieria | Q12: Cuarter 1 | Y12: Cuarter 2 | Z12: 53043142 | AA12: 74596765 | AB12: 54585023 | AC12: 0 | AD12: 182224930 | AE12: 182224930
N13: 2022 | O13: Gastos de Oficina | P13: 41617780 | Q13: Cuarter 2 | Y13: Cuarter 3 | Z13: 45504378 | AA13: 69111531 | AB13: 43700189 | AD13: 158316098 | AE13: 158316098
N14: 2022 | O14: Gastos Operacionales | P14: 32614841 | Q14: Cuarter 2 | Y14: Cuarter 4 | Z14: 70146271 | AA14: 76094471 | AB14: 39983421 | AD14: 186224163 | AE14: 186224163
N15: 2022 | O15: Gastos de Viaje | P15: 911167 | Q15: Cuarter 2 | Y15: Total general | Z15: 210643406 | AA15: 278435459 | AB15: 191427007 | AC15: 0 | AD15: 680505872 | AE15: 680505872
N16: 2022 | O16: Siga Sonriendo | P16: 59560197 | Q16: Cuarter 2
N17: 2022 | O17: Gastos Financieros | P17: 53043142 | Q17: Cuarter 2
N18: 2022 | O18: Gastos de Personal | P18: 85141216 | Q18: Cuarter 2
N19: 2022 | O19: Gastos Extras | P19: 1.4391437e+08 | Q19: Cuarter 2
N20: 2022 | O20: Gastos Tax Ingenieria | P20: 43286435 | Q20: Cuarter 2
N21: 2022 | O21: Gastos de Oficina | P21: 28667274 | Q21: Cuarter 3
N22: 2022 | O22: Gastos Operacionales | P22: 31407638 | Q22: Cuarter 3
N23: 2022 | O23: Gastos de Viaje | P23: 668827 | Q23: Cuarter 3
N24: 2022 | O24: Siga Sonriendo | P24: 36824033 | Q24: Cuarter 3
N25: 2022 | O25: Gastos Financieros | P25: 45504378 | Q25: Cuarter 3
N26: 2022 | O26: Gastos de Personal | P26: 66117646 | Q26: Cuarter 3
N27: 2022 | O27: Gastos Extras | P27: 1.1302042e+08 | Q27: Cuarter 3
... N104: 2024 | O104: Gastos Tax Ingenieria | P104: 5506789 | Q104: Cuarter 4
N105: 2025 | O105: Gastos de Oficina | P105: =+'2024&2023& 2022 G. Extra'!C9 -> 39542991 | Q105: Cuarter 1
N106: 2025 | O106: Gastos Operacionales | P106: =+'2024&2023& 2022 G. Extra'!C10 -> 0 | Q106: Cuarter 1
N107: 2025 | O107: Gastos de Viaje | P107: =+'2024&2023& 2022 G. Extra'!C11 -> 0 | Q107: Cuarter 1
N108: 2025 | O108: Siga Sonriendo | P108: =+'2024&2023& 2022 G. Extra'!C12 -> 0 | Q108: Cuarter 1
N109: 2025 | O109: Gastos Financieros | P109: =+'2024&2023& 2022 G. Extra'!C13 -> 0 | Q109: Cuarter 1
N110: 2025 | O110: Gastos de Personal | P110: =+'2024&2023& 2022 G. Extra'!C14 -> 0 | Q110: Cuarter 1
N111: 2025 | O111: Gastos de Marketing y Publicidad | P111: =+'2024&2023& 2022 G. Extra'!C15 -> 0 | Q111: Cuarter 1
N112: 2025 | O112: Gastos Extras | P112: =+'2024&2023& 2022 G. Extra'!C16 -> 0 | Q112: Cuarter 1
N113: 2025 | O113: Gastos Tax Ingenieria | P113: =+'2024&2023& 2022 G. Extra'!C17 -> 0 | Q113: Cuarter 1
N114: 2025 | O114: Gastos de Oficina | P114: =+'2024&2023& 2022 G. Extra'!D9 -> 59196948 | Q114: Cuarter 2
N115: 2025 | O115: Gastos Operacionales | P115: =+'2024&2023& 2022 G. Extra'!D10 -> 0 | Q115: Cuarter 2
N116: 2025 | O116: Gastos de Viaje | P116: =+'2024&2023& 2022 G. Extra'!D11 -> 0 | Q116: Cuarter 2
N117: 2025 | O117: Siga Sonriendo | P117: =+'2024&2023& 2022 G. Extra'!D12 -> 0 | Q117: Cuarter 2
...

Sheet Gastos Generales
B5: Cuenta | C5: Subcuenta | D5: january | E5: february | F5: march | G5: cuarter 1 | H5: april | I5: may | J5: june | K5: cuarter 2 | L5: july | M5: august | N5: september | O5: cuarter 3 | P5: october | Q5: november | R5: december | S5: cuarter 4 | T5: Total
B6: Gastos de Oficina | C6: EMPRESA RECICLADORA PLANETA LIMPIO | D6: =_xlfn.XLOOKUP(C6,[3]Gastos!$B:$B,[3]Gastos!$G:$G) -> 0 | E6: =_xlfn.XLOOKUP(C6,[3]Gastos!$B:$B,[3]Gastos!$L:$L) -> 0 | F6: =_xlfn.XLOOKUP(C6,[3]Gastos!$B:$B,[3]Gastos!$Q:$Q) -> 0 | G6: =SUM(Tabla1[[#This Row],[january]:[march]]) -> 0 | H6: =_xlfn.XLOOKUP(C6,[3]Gastos!$B:$B,[3]Gastos!$V:$V) -> 119540 | I6: =_xlfn.XLOOKUP(C6,[3]Gastos!$B:$B,[3]Gastos!$AA:$AA) -> 215654 | J6: =_xlfn.XLOOKUP(C6,[3]Gastos!$B:$B,[3]Gastos!$AF:$AF) -> 107327 | K6: =SUM(Tabla1[[#This Row],[april]:[june]]) -> 442521 | L6: =_xlfn.XLOOKUP(C6,[3]Gastos!$B:$B,[3]Gastos!$AK:$AK) -> 214680 | M6: =_xlfn.XLOOKUP(C6,[3]Gastos!$B:$B,[3]Gastos!$AP:$AP) -> 107198 | N6: =_xlfn.XLOOKUP(Tabla1[[#This Row],[Subcuenta]],[3]Gastos!$B:$B,[3]Gastos!$AU:$AU) -> 311506 | O6: =SUM(Tabla1[[#This Row],[july]:[september]]) -> 633384 | P6: =_xlfn.XLOOKUP(Tabla1[[#This Row],[Subcuenta]],[3]Gastos!$B:$B,[3]Gastos!$AZ:$AZ) -> 203427 | Q6: =_xlfn.XLOOKUP(Tabla1[[#This Row],[Subcuenta]],[3]Gastos!$B:$B,[3]Gastos!$BE:$BE) -> 222773 | R6: =_xlfn.XLOOKUP(Tabla1[[#This Row],[Subcuenta]],[3]Gastos!$B:$B,[3]Gastos!$BJ:$BJ) -> 299822 | S6: =SUM(Tabla1[[#This Row],[october]:[december]]) -> 726022 | T6: =SUM(G6,K6,O6,S6) -> 1801927
B7: Gastos de Oficina | C7: Equipos de protección al Personal | D7: =_xlfn.XLOOKUP(C7,[3]Gastos!$B:$B,[3]Gastos!$G:$G) -> 0 | E7: =_xlfn.XLOOKUP(C7,[3]Gastos!$B:$B,[3]Gastos!$L:$L) -> 0 | F7: =_xlfn.XLOOKUP(C7,[3]Gastos!$B:$B,[3]Gastos!$Q:$Q) -> 0 | G7: =SUM(Tabla1[[#This Row],[january]:[march]]) -> 0 | H7: =_xlfn.XLOOKUP(C7,[3]Gastos!$B:$B,[3]Gastos!$V:$V) -> 0 | I7: =_xlfn.XLOOKUP(C7,[3]Gastos!$B:$B,[3]Gastos!$AA:$AA) -> 0 | J7: =_xlfn.XLOOKUP(C7,[3]Gastos!$B:$B,[3]Gastos!$AF:$AF) -> 0 | K7: =SUM(Tabla1[[#This Row],[april]:[june]]) -> 0 | L7: =_xlfn.XLOOKUP(C7,[3]Gastos!$B:$B,[3]Gastos!$AK:$AK) -> 0 | M7: =_xlfn.XLOOKUP(C7,[3]Gastos!$B:$B,[3]Gastos!$AP:$AP) -> 0 | N7: =_xlfn.XLOOKUP(Tabla1[[#This Row],[Subcuenta]],[3]Gastos!$B:$B,[3]Gastos!$AU:$AU) -> 1107520 | O7: =SUM(Tabla1[[#This Row],[july]:[september]]) -> 1107520 | P7: =_xlfn.XLOOKUP(Tabla1[[#This Row],[Subcuenta]],[3]Gastos!$B:$B,[3]Gastos!$AZ:$AZ) -> 5523028 | Q7: =_xlfn.XLOOKUP(Tabla1[[#This Row],[Subcuenta]],[3]Gastos!$B:$B,[3]Gastos!$BE:$BE) -> 195200 | R7: =_xlfn.XLOOKUP(Tabla1[[#This Row],[Subcuenta]],[3]Gastos!$B:$B,[3]Gastos!$BJ:$BJ) -> 1787475 | S7: =SUM(Tabla1[[#This Row],[october]:[december]]) -> 7505703 | T7: =SUM(G7,K7,O7,S7) -> 8613223
B8: Gastos de Oficina | C8: Articulos de OFICINA (Dimerc, TodoToner) | D8: =_xlfn.XLOOKUP(C8,[3]Gastos!$B:$B,[3]Gastos!$G:$G) -> 486440 | E8: =_xlfn.XLOOKUP(C8,[3]Gastos!$B:$B,[3]Gastos!$L:$L) -> 643380 | F8: =_xlfn.XLOOKUP(C8,[3]Gastos!$B:$B,[3]Gastos!$Q:$Q) -> 782873 | G8: =SUM(Tabla1[[#This Row],[january]:[march]]) -> 1912693 | H8: =_xlfn.XLOOKUP(C8,[3]Gastos!$B:$B,[3]Gastos!$V:$V) -> 499369 | I8: =_xlfn.XLOOKUP(C8,[3]Gastos!$B:$B,[3]Gastos!$AA:$AA) -> 475469 | J8: =_xlfn.XLOOKUP(C8,[3]Gastos!$B:$B,[3]Gastos!$AF:$AF) -> 439479 | K8: =SUM(Tabla1[[#This Row],[april]:[june]]) -> 1414317 | L8: =_xlfn.XLOOKUP(C8,[3]Gastos!$B:$B,[3]Gastos!$AK:$AK) -> 302827 | M8: =_xlfn.XLOOKUP(C8,[3]Gastos!$B:$B,[3]Gastos!$AP:$AP) -> 754895 | N8: =_xlfn.XLOOKUP(Tabla1[[#This Row],[Subcuenta]],[3]Gastos!$B:$B,[3]Gastos!$AU:$AU) -> 490595 | O8: =SUM(Tabla1[[#This Row],[july]:[september]]) -> 1548317 | P8: =_xlfn.XLOOKUP(Tabla1[[#This Row],[Subcuenta]],[3]Gastos!$B:$B,[3]Gastos!$AZ:$AZ) -> 616738 | Q8: =_xlfn.XLOOKUP(Tabla1[[#This Row],[Subcuenta]],[3]Gastos!$B:$B,[3]Gastos!$BE:$BE) -> 405348 | R8: =_xlfn.XLOOKUP(Tabla1[[#This Row],[Subcuenta]],[3]Gastos!$B:$B,[3]Gastos!$BJ:$BJ) -> 0 | S8: =SUM(Tabla1[[#This Row],[october]:[december]]) -> 1022086 | T8: =SUM(G8,K8,O8,S8) -> 5897413
B9: Gastos de Oficina | C9: AGUA MINERAL | D9: =_xlfn.XLOOKUP(C9,[3]Gastos!$B:$B,[3]Gastos!$G:$G) -> 60000 | E9: =_xlfn.XLOOKUP(C9,[3]Gastos!$B:$B,[3]Gastos!$L:$L) -> 75000 | F9: =_xlfn.XLOOKUP(C9,[3]Gastos!$B:$B,[3]Gastos!$Q:$Q) -> 108000 | G9: =SUM(Tabla1[[#This Row],[january]:[march]]) -> 243000 | H9: =_xlfn.XLOOKUP(C9,[3]Gastos!$B:$B,[3]Gastos!$V:$V) -> 0 | I9: =_xlfn.XLOOKUP(C9,[3]Gastos!$B:$B,[3]Gastos!$AA:$AA) -> 123000 | J9: =_xlfn.XLOOKUP(C9,[3]Gastos!$B:$B,[3]Gastos!$AF:$AF) -> 0 | K9: =SUM(Tabla1[[#This Row],[april]:[june]]) -> 123000 | L9: =_xlfn.XLOOKUP(C9,[3]Gastos!$B:$B,[3]Gastos!$AK:$AK) -> 54000 | M9: =_xlfn.XLOOKUP(C9,[3]Gastos!$B:$B,[3]Gastos!$AP:$AP) -> 48000 | N9: =_xlfn.XLOOKUP(Tabla1[[#This Row],[Subcuenta]],[3]Gastos!$B:$B,[3]Gastos!$AU:$AU) -> 120000 | O9: =SUM(Tabla1[[#This Row],[july]:[september]]) -> 222000 | P9: =_xlfn.XLOOKUP(Tabla1[[#This Row],[Subcuenta]],[3]Gastos!$B:$B,[3]Gastos!$AZ:$AZ) -> 72000 | Q9: =_xlfn.XLOOKUP(Tabla1[[#This Row],[Subcuenta]],[3]Gastos!$B:$B,[3]Gastos!$BE:$BE) -> 0 | R9: =_xlfn.XLOOKUP(Tabla1[[#This Row],[Subcuenta]],[3]Gastos!$B:$B,[3]Gastos!$BJ:$BJ) -> 57000 | S9: =SUM(Tabla1[[#This Row],[october]:[december]]) -> 129000 | T9: =SUM(G9,K9,O9,S9) -> 717000
